<sdf version='1.7'>
  <world name='default'>
    <light name='sun' type='directional'>
      <cast_shadows>1</cast_shadows>
      <pose>0 0 10 0 -0 0</pose>
      <diffuse>0.8 0.8 0.8 1</diffuse>
      <specular>0.2 0.2 0.2 1</specular>
      <attenuation>
        <range>1000</range>
        <constant>0.9</constant>
        <linear>0.01</linear>
        <quadratic>0.001</quadratic>
      </attenuation>
      <direction>-0.5 0.1 -0.9</direction>
      <spot>
        <inner_angle>0</inner_angle>
        <outer_angle>0</outer_angle>
        <falloff>0</falloff>
      </spot>
    </light>
    <model name='ground_plane'>
      <static>1</static>
      <link name='link'>
        <collision name='collision'>
          <geometry>
            <plane>
              <normal>0 0 1</normal>
              <size>100 100</size>
            </plane>
          </geometry>
          <surface>
            <friction>
              <ode>
                <mu>100</mu>
                <mu2>50</mu2>
              </ode>
              <torsional>
                <ode/>
              </torsional>
            </friction>
            <contact>
              <ode/>
            </contact>
            <bounce/>
          </surface>
          <max_contacts>10</max_contacts>
        </collision>
        <visual name='visual'>
          <cast_shadows>0</cast_shadows>
          <geometry>
            <plane>
              <normal>0 0 1</normal>
              <size>100 100</size>
            </plane>
          </geometry>
          <material>
            <script>
              <uri>file://media/materials/scripts/gazebo.material</uri>
              <name>Gazebo/Grey</name>
            </script>
          </material>
        </visual>
        <self_collide>0</self_collide>
        <enable_wind>0</enable_wind>
        <kinematic>0</kinematic>
      </link>
    </model>
    <gravity>0 0 -9.8</gravity>
    <magnetic_field>6e-06 2.3e-05 -4.2e-05</magnetic_field>
    <atmosphere type='adiabatic'/>
    <physics type='ode'>
      <max_step_size>0.001</max_step_size>
      <real_time_factor>1</real_time_factor>
      <real_time_update_rate>1000</real_time_update_rate>
    </physics>
    <scene>
      <ambient>0.4 0.4 0.4 1</ambient>
      <background>0.7 0.7 0.7 1</background>
      <shadows>1</shadows>
    </scene>
    <audio>
      <device>default</device>
    </audio>
    <wind/>
    <spherical_coordinates>
      <surface_model>EARTH_WGS84</surface_model>
      <latitude_deg>0</latitude_deg>
      <longitude_deg>0</longitude_deg>
      <elevation>0</elevation>
      <heading_deg>0</heading_deg>
    </spherical_coordinates>
    <model name='Franka_Panda'>
      <joint name='robot_to_world' type='fixed'>
        <pose relative_to='__model__'>0 0 1 0 -0 0</pose>
        <parent>world</parent>
        <child>panda_link0</child>
      </joint>
      <link name='panda_link0'>
        <pose relative_to='robot_to_world'>0 0 0 0 -0 0</pose>
        <inertial>
          <pose>-0.02919 -0.000879 0.056603 0 -0 0</pose>
          <mass>3.06357</mass>
          <inertia>
            <ixx>0.009</ixx>
            <ixy>0</ixy>
            <ixz>-0.0001</ixz>
            <iyy>0.0122</iyy>
            <iyz>0</iyz>
            <izz>0.0122</izz>
          </inertia>
        </inertial>
        <collision name='panda_link0_collision'>
          <pose>0 0 0 0 -0 0</pose>
          <geometry>
            <mesh>
              <scale>1 1 1</scale>
              <uri>file:///home/luisc/workspaces/ws_manipulator/install/manipulator/share/manipulator/resource/meshes/collision/link0.stl</uri>
            </mesh>
          </geometry>
          <surface>
            <contact>
              <ode>
                <kp>0</kp>
                <kd>0</kd>
              </ode>
            </contact>
            <friction>
              <ode>
                <mu>0</mu>
                <mu2>0</mu2>
              </ode>
              <torsional>
                <ode/>
              </torsional>
            </friction>
            <bounce/>
          </surface>
          <max_contacts>10</max_contacts>
        </collision>
        <visual name='panda_link0_visual'>
          <pose>0 0 0 0 -0 0</pose>
          <geometry>
            <mesh>
              <scale>1 1 1</scale>
              <uri>file:///home/luisc/workspaces/ws_manipulator/install/manipulator/share/manipulator/resource/meshes/visual/link0.dae</uri>
            </mesh>
          </geometry>
        </visual>
        <self_collide>0</self_collide>
        <enable_wind>0</enable_wind>
        <kinematic>0</kinematic>
        <min_depth>0</min_depth>
        <slip1>0</slip1>
        <slip2>0</slip2>
      </link>
      <joint name='panda_joint1' type='revolute'>
        <pose relative_to='panda_link0'>0 0 0.333 0 -0 0</pose>
        <parent>panda_link0</parent>
        <child>panda_link1</child>
        <axis>
          <xyz>0 0 1</xyz>
          <limit>
            <lower>-3.14159</lower>
            <upper>3.14159</upper>
            <effort>87</effort>
            <velocity>2.175</velocity>
          </limit>
          <dynamics>
            <damping>1</damping>
            <friction>0</friction>
            <spring_reference>0</spring_reference>
            <spring_stiffness>0</spring_stiffness>
          </dynamics>
        </axis>
      </joint>
      <link name='panda_link1'>
        <pose relative_to='panda_joint1'>0 0 0 0 -0 0</pose>
        <inertial>
          <pose>1.1e-05 -0.031266 -0.069373 0 -0 0</pose>
          <mass>2.34471</mass>
          <inertia>
            <ixx>0.01418</ixx>
            <ixy>0</ixy>
            <ixz>0</ixz>
            <iyy>0.01181</iyy>
            <iyz>0.00236</iyz>
            <izz>0.005515</izz>
          </inertia>
        </inertial>
        <collision name='panda_link1_collision'>
          <pose>0 0 0 0 -0 0</pose>
          <geometry>
            <mesh>
              <scale>1 1 1</scale>
              <uri>file:///home/luisc/workspaces/ws_manipulator/install/manipulator/share/manipulator/resource/meshes/collision/link1.stl</uri>
            </mesh>
          </geometry>
          <surface>
            <contact>
              <ode>
                <kp>0</kp>
                <kd>0</kd>
              </ode>
            </contact>
            <friction>
              <ode>
                <mu>0</mu>
                <mu2>0</mu2>
              </ode>
              <torsional>
                <ode/>
              </torsional>
            </friction>
            <bounce/>
          </surface>
          <max_contacts>10</max_contacts>
        </collision>
        <visual name='panda_link1_visual'>
          <pose>0 0 0 0 -0 0</pose>
          <geometry>
            <mesh>
              <scale>1 1 1</scale>
              <uri>file:///home/luisc/workspaces/ws_manipulator/install/manipulator/share/manipulator/resource/meshes/visual/link1.dae</uri>
            </mesh>
          </geometry>
        </visual>
        <self_collide>0</self_collide>
        <enable_wind>0</enable_wind>
        <kinematic>0</kinematic>
        <min_depth>0</min_depth>
        <slip1>0</slip1>
        <slip2>0</slip2>
      </link>
      <joint name='panda_joint2' type='revolute'>
        <pose relative_to='panda_link1'>0 0 0 -1.5708 0 0</pose>
        <parent>panda_link1</parent>
        <child>panda_link2</child>
        <axis>
          <xyz>0 0 1</xyz>
          <limit>
            <lower>-3.14159</lower>
            <upper>3.14159</upper>
            <effort>87</effort>
            <velocity>2.175</velocity>
          </limit>
          <dynamics>
            <damping>1</damping>
            <friction>0</friction>
            <spring_reference>0</spring_reference>
            <spring_stiffness>0</spring_stiffness>
          </dynamics>
        </axis>
      </joint>
      <link name='panda_link2'>
        <pose relative_to='panda_joint2'>0 0 0 0 -0 0</pose>
        <inertial>
          <pose>-1.3e-05 -0.070322 0.031178 0 -0 0</pose>
          <mass>2.36414</mass>
          <inertia>
            <ixx>0.014</ixx>
            <ixy>0</ixy>
            <ixz>0</ixz>
            <iyy>0.0055</iyy>
            <iyz>-0.0023</iyz>
            <izz>0.01259</izz>
          </inertia>
        </inertial>
        <collision name='panda_link2_collision'>
          <pose>0 0 0 0 -0 0</pose>
          <geometry>
            <mesh>
              <scale>1 1 1</scale>
              <uri>file:///home/luisc/workspaces/ws_manipulator/install/manipulator/share/manipulator/resource/meshes/collision/link2.stl</uri>
            </mesh>
          </geometry>
          <surface>
            <contact>
              <ode/>
            </contact>
            <friction>
              <ode>
                <mu>0.61</mu>
                <mu2>0.61</mu2>
              </ode>
              <torsional>
                <ode/>
              </torsional>
            </friction>
            <bounce/>
          </surface>
          <max_contacts>10</max_contacts>
        </collision>
        <visual name='panda_link2_visual'>
          <pose>0 0 0 0 -0 0</pose>
          <geometry>
            <mesh>
              <scale>1 1 1</scale>
              <uri>file:///home/luisc/workspaces/ws_manipulator/install/manipulator/share/manipulator/resource/meshes/visual/link2.dae</uri>
            </mesh>
          </geometry>
        </visual>
        <self_collide>0</self_collide>
        <enable_wind>0</enable_wind>
        <kinematic>0</kinematic>
      </link>
      <joint name='panda_joint3' type='revolute'>
        <pose relative_to='panda_link2'>0 -0.316 0 1.5708 -0 0</pose>
        <parent>panda_link2</parent>
        <child>panda_link3</child>
        <axis>
          <xyz>0 0 1</xyz>
          <limit>
            <lower>-3.14159</lower>
            <upper>3.14159</upper>
            <effort>87</effort>
            <velocity>2.175</velocity>
          </limit>
          <dynamics>
            <damping>1</damping>
            <friction>0</friction>
            <spring_reference>0</spring_reference>
            <spring_stiffness>0</spring_stiffness>
          </dynamics>
        </axis>
      </joint>
      <link name='panda_link3'>
        <pose relative_to='panda_joint3'>0 0 0 0 -0 0</pose>
        <inertial>
          <pose>0.044348 0.024928 -0.03813 0 -0 0</pose>
          <mass>2.3805</mass>
          <inertia>
            <ixx>0.00716</ixx>
            <ixy>-0.00102</ixy>
            <ixz>-0.0204</ixz>
            <iyy>0.0092</iyy>
            <iyz>-0.00102</iyz>
            <izz>0.007159</izz>
          </inertia>
        </inertial>
        <collision name='panda_link3_collision'>
          <pose>0 0 0 0 -0 0</pose>
          <geometry>
            <mesh>
              <scale>1 1 1</scale>
              <uri>file:///home/luisc/workspaces/ws_manipulator/install/manipulator/share/manipulator/resource/meshes/collision/link3.stl</uri>
            </mesh>
          </geometry>
          <surface>
            <contact>
              <ode/>
            </contact>
            <friction>
              <ode>
                <mu>0.61</mu>
                <mu2>0.61</mu2>
              </ode>
              <torsional>
                <ode/>
              </torsional>
            </friction>
            <bounce/>
          </surface>
          <max_contacts>10</max_contacts>
        </collision>
        <visual name='panda_link3_visual'>
          <pose>0 0 0 0 -0 0</pose>
          <geometry>
            <mesh>
              <scale>1 1 1</scale>
              <uri>file:///home/luisc/workspaces/ws_manipulator/install/manipulator/share/manipulator/resource/meshes/visual/link3.dae</uri>
            </mesh>
          </geometry>
        </visual>
        <self_collide>0</self_collide>
        <enable_wind>0</enable_wind>
        <kinematic>0</kinematic>
      </link>
      <joint name='panda_joint4' type='revolute'>
        <pose relative_to='panda_link3'>0.0825 0 0 1.5708 -0 0</pose>
        <parent>panda_link3</parent>
        <child>panda_link4</child>
        <axis>
          <xyz>0 0 1</xyz>
          <limit>
            <lower>-3.14159</lower>
            <upper>3.14159</upper>
            <effort>87</effort>
            <velocity>2.175</velocity>
          </limit>
          <dynamics>
            <damping>1</damping>
            <friction>0</friction>
            <spring_reference>0</spring_reference>
            <spring_stiffness>0</spring_stiffness>
          </dynamics>
        </axis>
      </joint>
      <link name='panda_link4'>
        <pose relative_to='panda_joint4'>0 0 0 0 -0 0</pose>
        <inertial>
          <pose>-0.03855 0.039526 0.024716 0 -0 0</pose>
          <mass>2.42754</mass>
          <inertia>
            <ixx>0.008164</ixx>
            <ixy>0.003061</ixy>
            <ixz>0.00102</ixz>
            <iyy>0.008165</iyy>
            <iyz>0.00102</iyz>
            <izz>0.009185</izz>
          </inertia>
        </inertial>
        <collision name='panda_link4_collision'>
          <pose>0 0 0 0 -0 0</pose>
          <geometry>
            <mesh>
              <scale>1 1 1</scale>
              <uri>file:///home/luisc/workspaces/ws_manipulator/install/manipulator/share/manipulator/resource/meshes/collision/link4.stl</uri>
            </mesh>
          </geometry>
          <surface>
            <contact>
              <ode/>
            </contact>
            <friction>
              <ode>
                <mu>0.61</mu>
                <mu2>0.61</mu2>
              </ode>
              <torsional>
                <ode/>
              </torsional>
            </friction>
            <bounce/>
          </surface>
          <max_contacts>10</max_contacts>
        </collision>
        <visual name='panda_link4_visual'>
          <pose>0 0 0 0 -0 0</pose>
          <geometry>
            <mesh>
              <scale>1 1 1</scale>
              <uri>file:///home/luisc/workspaces/ws_manipulator/install/manipulator/share/manipulator/resource/meshes/visual/link4.dae</uri>
            </mesh>
          </geometry>
        </visual>
        <self_collide>0</self_collide>
        <enable_wind>0</enable_wind>
        <kinematic>0</kinematic>
      </link>
      <joint name='panda_joint5' type='revolute'>
        <pose relative_to='panda_link4'>-0.0825 0.384 0 -1.5708 0 0</pose>
        <parent>panda_link4</parent>
        <child>panda_link5</child>
        <axis>
          <xyz>0 0 1</xyz>
          <limit>
            <lower>-3.14159</lower>
            <upper>3.14159</upper>
            <effort>87</effort>
            <velocity>2.175</velocity>
          </limit>
          <dynamics>
            <damping>1</damping>
            <friction>0</friction>
            <spring_reference>0</spring_reference>
            <spring_stiffness>0</spring_stiffness>
          </dynamics>
        </axis>
      </joint>
      <link name='panda_link5'>
        <pose relative_to='panda_joint5'>0 0 0 0 -0 0</pose>
        <inertial>
          <pose>-6.4e-05 0.038412 -0.10997 0 -0 0</pose>
          <mass>3.49611</mass>
          <inertia>
            <ixx>0.0307</ixx>
            <ixy>0</ixy>
            <ixz>0</ixz>
            <iyy>0.02761</iyy>
            <iyz>-0.0613</iyz>
            <izz>0.00818</izz>
          </inertia>
        </inertial>
        <collision name='panda_link5_collision'>
          <pose>0 0 0 0 -0 0</pose>
          <geometry>
            <mesh>
              <scale>1 1 1</scale>
              <uri>file:///home/luisc/workspaces/ws_manipulator/install/manipulator/share/manipulator/resource/meshes/collision/link5.stl</uri>
            </mesh>
          </geometry>
          <surface>
            <contact>
              <ode/>
            </contact>
            <friction>
              <ode>
                <mu>0.61</mu>
                <mu2>0.61</mu2>
              </ode>
              <torsional>
                <ode/>
              </torsional>
            </friction>
            <bounce/>
          </surface>
          <max_contacts>10</max_contacts>
        </collision>
        <visual name='panda_link5_visual'>
          <pose>0 0 0 0 -0 0</pose>
          <geometry>
            <mesh>
              <scale>1 1 1</scale>
              <uri>file:///home/luisc/workspaces/ws_manipulator/install/manipulator/share/manipulator/resource/meshes/visual/link5.dae</uri>
            </mesh>
          </geometry>
        </visual>
        <self_collide>0</self_collide>
        <enable_wind>0</enable_wind>
        <kinematic>0</kinematic>
      </link>
      <joint name='panda_joint6' type='revolute'>
        <pose relative_to='panda_link5'>0 0 0 1.5708 -0 0</pose>
        <parent>panda_link5</parent>
        <child>panda_link6</child>
        <axis>
          <xyz>0 0 1</xyz>
          <limit>
            <lower>-3.14159</lower>
            <upper>3.14159</upper>
            <effort>87</effort>
            <velocity>2.175</velocity>
          </limit>
          <dynamics>
            <damping>1</damping>
            <friction>0</friction>
            <spring_reference>0</spring_reference>
            <spring_stiffness>0</spring_stiffness>
          </dynamics>
        </axis>
      </joint>
      <link name='panda_link6'>
        <pose relative_to='panda_joint6'>0 0 0 0 -0 0</pose>
        <inertial>
          <pose>0.051002 0.006933 0.006169 0 -0 0</pose>
          <mass>1.46736</mass>
          <inertia>
            <ixx>0.00205</ixx>
            <ixy>0</ixy>
            <ixz>0</ixz>
            <iyy>0.004089</iyy>
            <iyz>0</iyz>
            <izz>0.0049</izz>
          </inertia>
        </inertial>
        <collision name='panda_link6_collision'>
          <pose>0 0 0 0 -0 0</pose>
          <geometry>
            <mesh>
              <scale>1 1 1</scale>
              <uri>file:///home/luisc/workspaces/ws_manipulator/install/manipulator/share/manipulator/resource/meshes/collision/link6.stl</uri>
            </mesh>
          </geometry>
          <surface>
            <contact>
              <ode>
                <kp>100000</kp>
                <kd>100</kd>
              </ode>
            </contact>
            <friction>
              <ode>
                <mu2>0.5</mu2>
              </ode>
              <torsional>
                <ode/>
              </torsional>
            </friction>
            <bounce/>
          </surface>
          <max_contacts>10</max_contacts>
        </collision>
        <visual name='panda_link6_visual'>
          <pose>0 0 0 0 -0 0</pose>
          <geometry>
            <mesh>
              <scale>1 1 1</scale>
              <uri>file:///home/luisc/workspaces/ws_manipulator/install/manipulator/share/manipulator/resource/meshes/visual/link6.dae</uri>
            </mesh>
          </geometry>
        </visual>
        <self_collide>0</self_collide>
        <enable_wind>0</enable_wind>
        <kinematic>0</kinematic>
        <min_depth>0</min_depth>
        <slip1>0.2</slip1>
        <slip2>0.2</slip2>
        <mu>0.81</mu>
      </link>
      <joint name='panda_joint7' type='revolute'>
        <pose relative_to='panda_link6'>0.088 0 0 1.5708 -0 0</pose>
        <parent>panda_link6</parent>
        <child>panda_link7</child>
        <axis>
          <xyz>0 0 1</xyz>
          <limit>
            <lower>-2.8973</lower>
            <upper>2.8973</upper>
            <effort>12</effort>
            <velocity>2.61</velocity>
          </limit>
          <dynamics>
            <damping>1</damping>
            <friction>0</friction>
            <spring_reference>0</spring_reference>
            <spring_stiffness>0</spring_stiffness>
          </dynamics>
        </axis>
      </joint>
      <link name='panda_link7'>
        <pose relative_to='panda_joint7'>0 0 0 0 -0 0</pose>
        <inertial>
          <pose>0 0 0.065835 0 -0 0</pose>
          <mass>1.15706</mass>
          <inertia>
            <ixx>0.703331</ixx>
            <ixy>1.38778e-17</ixy>
            <ixz>0</ixz>
            <iyy>0.703331</iyy>
            <iyz>0</iyz>
            <izz>0.700001</izz>
          </inertia>
        </inertial>
        <collision name='panda_link7_collision'>
          <pose>0 0 0 0 -0 0</pose>
          <geometry>
            <mesh>
              <scale>1 1 1</scale>
              <uri>file:///home/luisc/workspaces/ws_manipulator/install/manipulator/share/manipulator/resource/meshes/collision/link7.stl</uri>
            </mesh>
          </geometry>
          <surface>
            <contact>
              <ode>
                <kp>50000</kp>
                <kd>1</kd>
              </ode>
            </contact>
            <friction>
              <ode>
                <mu>0</mu>
                <mu2>0</mu2>
              </ode>
              <torsional>
                <ode/>
              </torsional>
            </friction>
            <bounce/>
          </surface>
          <max_contacts>10</max_contacts>
        </collision>
        <collision name='panda_link7_fixed_joint_lump__panda_hand_collision_1'>
          <pose>0 0 0.107 0 0 -0.785398</pose>
          <geometry>
            <mesh>
              <scale>1 1 1</scale>
              <uri>file:///home/luisc/workspaces/ws_manipulator/install/manipulator/share/manipulator/resource/meshes/collision/hand.stl</uri>
            </mesh>
          </geometry>
          <max_contacts>10</max_contacts>
          <surface>
            <contact>
              <ode/>
            </contact>
            <bounce/>
            <friction>
              <torsional>
                <ode/>
              </torsional>
              <ode/>
            </friction>
          </surface>
        </collision>
        <collision name='panda_link7_fixed_joint_lump__back_collision_2'>
          <pose>-0.014142 0.014142 0.1854 0 0 -0.785398</pose>
          <geometry>
            <box>
              <size>0.01 0.04 0.04</size>
            </box>
          </geometry>
          <max_contacts>10</max_contacts>
          <surface>
            <contact>
              <ode/>
            </contact>
            <bounce/>
            <friction>
              <torsional>
                <ode/>
              </torsional>
              <ode/>
            </friction>
          </surface>
        </collision>
        <collision name='panda_link7_fixed_joint_lump__left_collision_3'>
          <pose>-0.014142 -0.014142 0.1854 0 0 -0.785398</pose>
          <geometry>
            <box>
              <size>0.04 0.01 0.04</size>
            </box>
          </geometry>
          <max_contacts>10</max_contacts>
          <surface>
            <contact>
              <ode/>
            </contact>
            <bounce/>
            <friction>
              <torsional>
                <ode/>
              </torsional>
              <ode/>
            </friction>
          </surface>
        </collision>
        <collision name='panda_link7_fixed_joint_lump__right_collision_4'>
          <pose>0.014142 0.014142 0.1854 0 0 -0.785398</pose>
          <geometry>
            <box>
              <size>0.04 0.01 0.04</size>
            </box>
          </geometry>
          <max_contacts>10</max_contacts>
          <surface>
            <contact>
              <ode/>
            </contact>
            <bounce/>
            <friction>
              <torsional>
                <ode/>
              </torsional>
              <ode/>
            </friction>
          </surface>
        </collision>
        <collision name='panda_link7_fixed_joint_lump__front_collision_5'>
          <pose>0.014142 -0.014142 0.1854 0 0 -0.785398</pose>
          <geometry>
            <box>
              <size>0.01 0.04 0.04</size>
            </box>
          </geometry>
          <max_contacts>10</max_contacts>
          <surface>
            <contact>
              <ode/>
            </contact>
            <bounce/>
            <friction>
              <torsional>
                <ode/>
              </torsional>
              <ode/>
            </friction>
          </surface>
        </collision>
        <visual name='panda_link7_visual'>
          <pose>0 0 0 0 -0 0</pose>
          <geometry>
            <mesh>
              <scale>1 1 1</scale>
              <uri>file:///home/luisc/workspaces/ws_manipulator/install/manipulator/share/manipulator/resource/meshes/visual/link7.dae</uri>
            </mesh>
          </geometry>
        </visual>
        <visual name='panda_link7_fixed_joint_lump__panda_hand_visual_1'>
          <pose>0 0 0.107 0 0 -0.785398</pose>
          <geometry>
            <mesh>
              <scale>1 1 1</scale>
              <uri>file:///home/luisc/workspaces/ws_manipulator/install/manipulator/share/manipulator/resource/meshes/visual/hand.dae</uri>
            </mesh>
          </geometry>
        </visual>
        <visual name='panda_link7_fixed_joint_lump__back_visual_2'>
          <pose>-0.014142 0.014142 0.1854 0 0 -0.785398</pose>
          <geometry>
            <box>
              <size>0.01 0.04 0.04</size>
            </box>
          </geometry>
        </visual>
        <visual name='panda_link7_fixed_joint_lump__left_visual_3'>
          <pose>-0.014142 -0.014142 0.1854 0 0 -0.785398</pose>
          <geometry>
            <box>
              <size>0.04 0.01 0.04</size>
            </box>
          </geometry>
        </visual>
        <visual name='panda_link7_fixed_joint_lump__right_visual_4'>
          <pose>0.014142 0.014142 0.1854 0 0 -0.785398</pose>
          <geometry>
            <box>
              <size>0.04 0.01 0.04</size>
            </box>
          </geometry>
        </visual>
        <visual name='panda_link7_fixed_joint_lump__front_visual_5'>
          <pose>0.014142 -0.014142 0.1854 0 0 -0.785398</pose>
          <geometry>
            <box>
              <size>0.01 0.04 0.04</size>
            </box>
          </geometry>
        </visual>
        <self_collide>0</self_collide>
        <enable_wind>0</enable_wind>
        <kinematic>0</kinematic>
        <min_depth>0</min_depth>
        <slip1>0</slip1>
        <slip2>0</slip2>
      </link>
      <plugin name='gazebo_ros_joint_state_publisher' filename='libgazebo_ros_joint_state_publisher.so'>
        <update_rate>1000</update_rate>
        <joint_name>panda_joint1</joint_name>
        <joint_name>panda_joint2</joint_name>
        <joint_name>panda_joint3</joint_name>
        <joint_name>panda_joint4</joint_name>
        <joint_name>panda_joint5</joint_name>
        <joint_name>panda_joint6</joint_name>
        <joint_name>panda_joint7</joint_name>
      </plugin>
      <static>0</static>
      <plugin name='gazebo_ros2_control' filename='libgazebo_ros2_control.so'>
        <parameters>/home/luisc/workspaces/ws_manipulator/install/manipulator/share/manipulator/config/controllers.yaml</parameters>
      </plugin>
      <pose>0 0 0 0 -0 0</pose>
    </model>
    <model name='unit_box'>
      <pose>0.316345 0.002475 0.5 0 -0 0</pose>
      <link name='link'>
        <inertial>
          <mass>1</mass>
          <inertia>
            <ixx>0.166667</ixx>
            <ixy>0</ixy>
            <ixz>0</ixz>
            <iyy>0.166667</iyy>
            <iyz>0</iyz>
            <izz>0.166667</izz>
          </inertia>
          <pose>0 0 0 0 -0 0</pose>
        </inertial>
        <collision name='collision'>
          <geometry>
            <box>
              <size>1 1 1</size>
            </box>
          </geometry>
          <max_contacts>10</max_contacts>
          <surface>
            <contact>
              <ode/>
            </contact>
            <bounce/>
            <friction>
              <torsional>
                <ode/>
              </torsional>
              <ode/>
            </friction>
          </surface>
        </collision>
        <visual name='visual'>
          <geometry>
            <box>
              <size>1 1 1</size>
            </box>
          </geometry>
          <material>
            <script>
              <name>Gazebo/Grey</name>
              <uri>file://media/materials/scripts/gazebo.material</uri>
            </script>
          </material>
        </visual>
        <self_collide>0</self_collide>
        <enable_wind>0</enable_wind>
        <kinematic>0</kinematic>
      </link>
    </model>
    <state world_name='default'>
      <sim_time>87 652000000</sim_time>
      <real_time>87 912677078</real_time>
      <wall_time>1718366094 858486023</wall_time>
      <iterations>87652</iterations>
      <model name='Franka_Panda'>
        <pose>-2e-06 3e-06 -0 3e-06 2e-06 0</pose>
        <scale>1 1 1</scale>
        <link name='panda_link0'>
          <pose>-0 0 1 3e-06 2e-06 0</pose>
          <velocity>-0 -0 -0 0 -0 0</velocity>
          <acceleration>3e-06 -1e-05 -2e-06 0.000119 0.000202 -7.4e-05</acceleration>
          <wrench>8e-06 -3.1e-05 -6e-06 0 -0 0</wrench>
        </link>
        <link name='panda_link1'>
          <pose>-2e-06 -1e-06 1.333 -5e-06 -8e-06 0.000218</pose>
          <velocity>-0 1e-06 -0 -2e-06 -1e-06 0.001055</velocity>
          <acceleration>0.032945 0.000779 1.3e-05 -0.001656 -0.000569 1.055</acceleration>
          <wrench>0.077247 0.001826 3e-05 0 -0 0</wrench>
        </link>
        <link name='panda_link2'>
          <pose>-2e-06 -1e-06 1.333 -1.57081 0.001172 0.000222</pose>
          <velocity>-0 1e-06 0 -2e-06 0.005253 0.001055</velocity>
          <acceleration>0.336396 0.00104 -0.000383 3.13834 0.908974 2.42665</acceleration>
          <wrench>0.795287 0.002459 -0.000906 0 -0 0</wrench>
        </link>
        <link name='panda_link3'>
          <pose>0.000367 4e-06 1.649 -1.4e-05 0.001173 -3e-06</pose>
          <velocity>0.00166 2e-06 -2e-06 -2e-06 0.005253 -9e-06</velocity>
          <acceleration>1.45941 0.001558 -0.23467 -0.001956 -1.03017 -0.009149</acceleration>
          <wrench>3.47413 0.003708 -0.558632 0 -0 0</wrench>
        </link>
        <link name='panda_link4'>
          <pose>0.082867 5e-06 1.6489 1.57079 -0.001155 -2e-06</pose>
          <velocity>0.001659 1e-06 -0.000435 -2e-06 -0.005248 -9e-06</velocity>
          <acceleration>1.45183 0.001721 -0.637755 -2.45658 1.30291 -0.367479</acceleration>
          <wrench>3.52438 0.004178 -1.54818 0 -0 0</wrench>
        </link>
        <link name='panda_link5'>
          <pose>-7.9e-05 8e-06 2.03281 -2.5e-05 -0.001155 5e-06</pose>
          <velocity>-0.000356 2e-06 -0.00087 -1e-06 -0.005248 3.3e-05</velocity>
          <acceleration>0.220319 0.001719 -0.870151 0.010859 1.03539 0.033559</acceleration>
          <wrench>0.770261 0.006008 -3.04214 0 -0 0</wrench>
        </link>
        <link name='panda_link6'>
          <pose>-7.9e-05 8e-06 2.03281 1.57078 0.000478 5e-06</pose>
          <velocity>-0.000356 2e-06 -0.00087 -1e-06 0.00214 3.3e-05</velocity>
          <acceleration>-0.34053 0.003538 -0.979544 3.14075 1.35602 -3.10179</acceleration>
          <wrench>-0.49968 0.005191 -1.43734 0 -0 0</wrench>
        </link>
        <link name='panda_link7'>
          <pose>0.087921 9e-06 2.03276 3.14157 0.000477 -0</pose>
          <velocity>-0.000356 5e-06 -0.001059 -3e-06 0.00214 -0</velocity>
          <acceleration>-0.496484 0.004574 -1.05863 3.13905 1.00175 3.14155</acceleration>
          <wrench>-0.574462 0.005293 -1.2249 0 -0 0</wrench>
        </link>
      </model>
      <model name='ground_plane'>
        <pose>0 0 0 0 -0 0</pose>
        <scale>1 1 1</scale>
        <link name='link'>
          <pose>0 0 0 0 -0 0</pose>
          <velocity>0 0 0 0 -0 0</velocity>
          <acceleration>0 0 0 0 -0 0</acceleration>
          <wrench>0 0 0 0 -0 0</wrench>
        </link>
      </model>
      <model name='unit_box'>
        <pose>-0.044559 0.004839 0.5 0 -0 0.000818</pose>
        <scale>0.276972 0.231094 1</scale>
        <link name='link'>
          <pose>-0.044559 0.004839 0.5 0 -0 0.000818</pose>
          <velocity>5e-06 1e-06 0.0098 -2e-06 9e-06 0</velocity>
          <acceleration>0.004589 0.000818 9.80047 -0.001615 0.009187 0.000211</acceleration>
          <wrench>0.004589 0.000818 9.80047 0 -0 0</wrench>
        </link>
      </model>
      <light name='sun'>
        <pose>0 0 10 0 -0 0</pose>
      </light>
    </state>
    <gui fullscreen='0'>
      <camera name='user_camera'>
        <pose>3.40278 0.646251 3.15931 0 0.487644 -3.05899</pose>
        <view_controller>orbit</view_controller>
        <projection_type>perspective</projection_type>
      </camera>
    </gui>
  </world>
</sdf>
